Workbook

Sheet Definitions
A1: Surrounds | B1: Enclosed | C1: Transitive | D1: a and b have no interior points in common, and with holes filled b lies in the interior of a. | F1: region a region b intersection of a & b
A2: Shelters | B2: Sheltered | C2: Transitive | D2: a and b have no points in common, but the Convex Hull of a contains b. | F2: A relation is transitive if whenever ,aRb and bRc then aRc. For example, if a Contains b and b Contains c relation, then a Contains c.
A3: Disjoint | B3: Disjoint | C3: Symmetric | D3: a and b have no points in common. | F3: A relation is symmetric if aRb implies bRa for all a and b. For example, if a Equals b then b Equals a.
A4: Borders | B4: Borders | C4: Symmetric | D4: The exterior boundaries of a and b have more than one point in common, but their interiors do not intersect.
A5: Confines | B5: Confined | D5: The interior boundary of one shape a and the exterior boundary of another shape b have more than one point in common, but their interiors do not intersect.
A6: Overlaps | B6: Overlaps | C6: Symmetric | D6: a overlaps b: both have some but not all points in common.
A7: Partitioned | B7: Partitions | D7: All points of a lie in the interior of b, no points of a lie in the exterior of b, some points in b are exterior to a, and the boundaries of a and b have more than one point in common. | F7: .
A8: Overlaps | B8: Overlaps | C8: Symmetric | D8: a overlaps b: both have some but not all points in common.
A9: Contains | B9: Within | C9: Transitive | D9: All points of a lie in the interior of b, no points of a lie in the exterior of b, some points in b are exterior to a, and the boundaries of a and b do not intersect.
A10: Equals | B10: Equals | C10: Symmetric, Transitive | D10: The interiors of a and b intersect and no part of the interior of one geometry intersects the exterior of the other.

Sheet Descision Tree
B2: Not Up To Date

Sheet Descision Matrix
A2: Do the boundaries of A and B overlap? | B2: Yes | E2: B | K2: B | Q2: B | T2: Do the interiors of A and B overlap? | U2: Yes | X2: B | AD2: B | AJ2: B | AM2: Does the interior of A include the exterior of B? | AN2: Yes | AQ2: B | AW2: B | BC2: B | BF2: Does the interior of B include the exterior of A? | BG2: Yes | BJ2: B | BP2: B | BV2: B | BY2: A Overlaps B
E3: I | F3: B | G3: E | K3: I | L3: B | M3: E | Q3: I | R3: B | S3: E | X3: I | Y3: B | Z3: E | AD3: I | AE3: B | AF3: E | AJ3: I | AK3: B | AL3: E | AQ3: I | AR3: B | AS3: E | AW3: I | AX3: B | AY3: E | BC3: I | BD3: B | BE3: E | BJ3: I | BK3: B | BL3: E | BP3: I | BQ3: B | BR3: E | BV3: I | BW3: B | BX3: E
C4: A | D4: I | E4: * | F4: * | G4: * | I4: A | J4: I | K4: * | L4: * | M4: * | O4: A | P4: I | Q4: * | R4: * | S4: * | V4: A | W4: I | X4: T | Y4: * | Z4: * | AB4: A | AC4: I | AD4: * | AE4: * | AF4: * | AH4: A | AI4: I | AJ4: * | AK4: * | AL4: * | AO4: A | AP4: I | AQ4: T | AR4: * | AS4: T | AU4: A | AV4: I | AW4: * | AX4: * | AY4: * | BA4: A | BB4: I | BC4: * | BD4: * | BE4: * | BH4: A | BI4: I | BJ4: T | BK4: * | BL4: T | BN4: A | BO4: I | BP4: * | BQ4: * | BR4: * | BT4: A | BU4: I | BV4: * | BW4: * | BX4: *
D5: B | E5: * | F5: T | G5: * | J5: B | K5: * | L5: * | M5: * | P5: B | Q5: * | R5: * | S5: * | W5: B | X5: * | Y5: T | Z5: * | AC5: B | AD5: * | AE5: * | AF5: * | AI5: B | AJ5: * | AK5: * | AL5: * | AP5: B | AQ5: * | AR5: T | AS5: * | AV5: B | AW5: * | AX5: * | AY5: * | BB5: B | BC5: * | BD5: * | BE5: * | BI5: B | BJ5: * | BK5: * | BL5: * | BO5: B | BP5: * | BQ5: * | BR5: * | BU5: B | BV5: * | BW5: * | BX5: *
D6: E | E6: * | F6: * | G6: * | J6: E | K6: * | L6: * | M6: * | P6: E | Q6: * | R6: * | S6: * | W6: E | X6: * | Y6: * | Z6: * | AC6: E | AD6: * | AE6: * | AF6: * | AI6: E | AJ6: * | AK6: * | AL6: * | AP6: E | AQ6: * | AR6: * | AS6: * | AV6: E | AW6: * | AX6: * | AY6: * | BB6: E | BC6: * | BD6: * | BE6: * | BI6: E | BJ6: T | BK6: * | BL6: * | BO6: E | BP6: * | BQ6: * | BR6: * | BU6: E | BV6: * | BW6: * | BX6: *
BG8: No | BJ8: B | BP8: B | BV8: B | BY8: A is Partitioned by B
BJ9: I | BK9: B | BL9: E | BP9: I | BQ9: B | BR9: E | BV9: I | BW9: B | BX9: E
BH10: A | BI10: I | BJ10: T | BK10: * | BL10: T | BN10: A | BO10: I | BP10: * | BQ10: * | BR10: * | BT10: A | BU10: I | BV10: * | BW10: * | BX10: *
BI11: B | BJ11: * | BK11: T | BL11: * | BO11: B | BP11: * | BQ11: * | BR11: * | BU11: B | BV11: * | BW11: * | BX11: *
BI12: E | BJ12: F | BK12: * | BL12: * | BO12: E | BP12: * | BQ12: * | BR12: * | BU12: E | BV12: * | BW12: * | BX12: *
AN14: No | AQ14: B | AW14: B | BC14: B | BF14: Does the interior of B include the exterior of A? | BG14: Yes | BJ14: B | BP14: B | BV14: B | BY14: A Partitions B
AQ15: I | AR15: B | AS15: E | AW15: I | AX15: B | AY15: E | BC15: I | BD15: B | BE15: E | BJ15: I | BK15: B | BL15: E | BP15: I | BQ15: B | BR15: E | BV15: I | BW15: B | BX15: E
AO16: A | AP16: I | AQ16: T | AR16: * | AS16: F | AU16: A | AV16: I | AW16: * | AX16: * | AY16: * | BA16: A | BB16: I | BC16: * | BD16: * | BE16: * | BH16: A | BI16: I | BJ16: T | BK16: * | BL16: F | BN16: A | BO16: I | BP16: * | BQ16: * | BR16: * | BT16: A | BU16: I | BV16: * | BW16: * | BX16: *
AP17: B | AQ17: * | AR17: T | AS17: * | AV17: B | AW17: * | AX17: * | AY17: * | BB17: B | BC17: * | BD17: * | BE17: * | BI17: B | BJ17: * | BK17: T | BL17: * | BO17: B | BP17: * | BQ17: * | BR17: * | BU17: B | BV17: * | BW17: * | BX17: *
AP18: E | AQ18: * | AR18: * | AS18: * | AV18: E | AW18: * | AX18: * | AY18: * | BB18: E | BC18: * | BD18: * | BE18: * | BI18: E | BJ18: T | BK18: * | BL18: * | BO18: E | BP18: * | BQ18: * | BR18: * | BU18: E | BV18: * | BW18: * | BX18: *
BG20: No | BJ20: B | BP20: B | BV20: B | BY20: A Equals B
BJ21: I | BK21: B | BL21: E | BP21: I | BQ21: B | BR21: E | BV21: I | BW21: B | BX21: E
BH22: A | BI22: I | BJ22: T | BK22: * | BL22: F | BN22: A | BO22: I | BP22: * | BQ22: * | BR22: * | BT22: A | BU22: I | BV22: * | BW22: * | BX22: *
BI23: B | BJ23: * | BK23: T | BL23: * | BO23: B | BP23: * | BQ23: * | BR23: * | BU23: B | BV23: * | BW23: * | BX23: *
BI24: E | BJ24: F | BK24: * | BL24: * | BO24: E | BP24: * | BQ24: * | BR24: * | BU24: E | BV24: * | BW24: * | BX24: *
U26: No | X26: B | AD26: B | AJ26: B | AM26: Do the external bounds of A contain the external bounds of B? | AN26: Yes | AQ26: B | AW26: B | BC26: B | BF26: Do the external bounds of A exist outside the external bounds of B? | BG26: Yes | BJ26: B | BP26: B | BV26: B | BY26: Do the external bounds of B exist outside the external bounds of A? | BZ26: No | CC26: B | CI26: B | CO26: B | CR26: Does the interior of A include the exterior of B? Does the interior of B include the exterior of A? | CS26: Yes | CV26: B | DB26: B | DH26: B | DK26: A Confines B
X27: I | Y27: B | Z27: E | AD27: I | AE27: B | AF27: E | AJ27: I | AK27: B | AL27: E | AQ27: I | AR27: B | AS27: E | AW27: I | AX27: B | AY27: E | BC27: I | BD27: B | BE27: E | BJ27: I | BK27: B | BL27: E | BP27: I | BQ27: B | BR27: E | BV27: I | BW27: B | BX27: E | CC27: I | CD27: B | CE27: E | CI27: I | CJ27: B | CK27: E | CO27: I | CP27: B | CQ27: E | CV27: I | CW27: B | CX27: E | DB27: I | DC27: B | DD27: E | DH27: I | DI27: B | DJ27: E
V28: A | W28: I | X28: F | Y28: * | Z28: * | AB28: A | AC28: I | AD28: * | AE28: * | AF28: * | AH28: A | AI28: I | AJ28: * | AK28: * | AL28: * | AO28: A | AP28: I | AQ28: F | AR28: * | AS28: * | AU28: A | AV28: I | AW28: T | AX28: * | AY28: * | BA28: A | BB28: I | BC28: * | BD28: * | BE28: * | BH28: A | BI28: I | BJ28: F | BK28: * | BL28: * | BN28: A | BO28: I | BP28: T | BQ28: * | BR28: T | BT28: A | BU28: I | BV28: * | BW28: * | BX28: * | CA28: A | CB28: I | CC28: F | CD28: * | CE28: * | CG28: A | CH28: I | CI28: T | CJ28: * | CK28: T | CM28: A | CN28: I | CO28: * | CP28: * | CQ28: * | CT28: A | CU28: I | CV28: F | CW28: * | CX28: T | CZ28: A | DA28: I | DB28: T | DC28: * | DD28: T | DF28: A | DG28: I | DH28: * | DI28: * | DJ28: *
W29: B | X29: * | Y29: T | Z29: * | AC29: B | AD29: * | AE29: * | AF29: * | AI29: B | AJ29: * | AK29: * | AL29: * | AP29: B | AQ29: * | AR29: T | AS29: * | AV29: B | AW29: * | AX29: * | AY29: * | BB29: B | BC29: * | BD29: * | BE29: * | BI29: B | BJ29: * | BK29: T | BL29: * | BO29: B | BP29: * | BQ29: * | BR29: * | BU29: B | BV29: * | BW29: * | BX29: * | CB29: B | CC29: * | CD29: T | CE29: * | CH29: B | CI29: * | CJ29: * | CK29: * | CN29: B | CO29: * | CP29: * | CQ29: * | CU29: B | CV29: * | CW29: T | CX29: * | DA29: B | DB29: * | DC29: * | DD29: * | DG29: B | DH29: * | DI29: * | DJ29: *
W30: E | X30: * | Y30: * | Z30: * | AC30: E | AD30: * | AE30: * | AF30: * | AI30: E | AJ30: * | AK30: * | AL30: * | AP30: E | AQ30: * | AR30: * | AS30: * | AV30: E | AW30: * | AX30: * | AY30: * | BB30: E | BC30: * | BD30: * | BE30: * | BI30: E | BJ30: * | BK30: * | BL30: * | BO30: E | BP30: * | BQ30: * | BR30: * | BU30: E | BV30: * | BW30: * | BX30: * | CB30: E | CC30: * | CD30: * | CE30: * | CH30: E | CI30: F | CJ30: * | CK30: * | CN30: E | CO30: * | CP30: * | CQ30: * | CU30: E | CV30: T | CW30: * | CX30: * | DA30: E | DB30: F | DC30: * | DD30: * | DG30: E | DH30: * | DI30: * | DJ30: *
BG32: No | BJ32: B | BP32: B | BV32: B | BY32: Do the external bounds of B exist outside the external bounds of A? | BZ32: Yes | CC32: B | CI32: B | CO32: B | CS32: Yes | CV32: B | DB32: B | DH32: B | DK32: A is Confined by B
BJ33: I | BK33: B | BL33: E | BP33: I | BQ33: B | BR33: E | BV33: I | BW33: B | BX33: E | CC33: I | CD33: B | CE33: E | CI33: I | CJ33: B | CK33: E | CO33: I | CP33: B | CQ33: E | CV33: I | CW33: B | CX33: E | DB33: I | DC33: B | DD33: E | DH33: I | DI33: B | DJ33: E
BH34: A | BI34: I | BJ34: F | BK34: * | BL34: * | BN34: A | BO34: I | BP34: T | BQ34: * | BR34: F | BT34: A | BU34: I | BV34: * | BW34: * | BX34: * | CA34: A | CB34: I | CC34: F | CD34: * | CE34: * | CG34: A | CH34: I | CI34: T | CJ34: * | CK34: F | CM34: A | CN34: I | CO34: * | CP34: * | CQ34: * | CT34: A | CU34: I | CV34: F | CW34: * | CX34: T | CZ34: A | DA34: I | DB34: T | DC34: * | DD34: F | DF34: A | DG34: I | DH34: * | DI34: * | DJ34: *
BI35: B | BJ35: * | BK35: T | BL35: * | BO35: B | BP35: * | BQ35: * | BR35: * | BU35: B | BV35: * | BW35: * | BX35: * | CB35: B | CC35: * | CD35: T | CE35: * | CH35: B | CI35: * | CJ35: * | CK35: * | CN35: B | CO35: * | CP35: * | CQ35: * | CU35: B | CV35: * | CW35: T | CX35: * | DA35: B | DB35: * | DC35: * | DD35: * | DG35: B | DH35: * | DI35: * | DJ35: *
BI36: E | BJ36: * | BK36: * | BL36: * | BO36: E | BP36: * | BQ36: * | BR36: * | BU36: E | BV36: * | BW36: * | BX36: * | CB36: E | CC36: * | CD36: * | CE36: * | CH36: E | CI36: T | CJ36: * | CK36: * | CN36: E | CO36: * | CP36: * | CQ36: * | CU36: E | CV36: T | CW36: * | CX36: * | DA36: E | DB36: T | DC36: * | DD36: * | DG36: E | DH36: * | DI36: * | DJ36: *
AN38: No | AQ38: B | AW38: B | BC38: B | BF38: Do the external bounds of B exist outside the external bounds of A? | BG38: Yes | BJ38: B | BP38: B | BV38: B | BY38: A Borders B | CC38: B | CI38: B | CO38: B | CR38: Should this be Possible?
AQ39: I | AR39: B | AS39: E | AW39: I | AX39: B | AY39: E | BC39: I | BD39: B | BE39: E | BJ39: I | BK39: B | BL39: E | BP39: I | BQ39: B | BR39: E | BV39: I | BW39: B | BX39: E | CC39: I | CD39: B | CE39: E | CI39: I | CJ39: B | CK39: E | CO39: I | CP39: B | CQ39: E
AO40: A | AP40: I | AQ40: F | AR40: * | AS40: * | AU40: A | AV40: I | AW40: F | AX40: * | AY40: * | BA40: A | BB40: I | BC40: * | BD40: * | BE40: * | BH40: A | BI40: I | BJ40: F | BK40: * | BL40: * | BN40: A | BO40: I | BP40: F | BQ40: * | BR40: T | BT40: A | BU40: I | BV40: * | BW40: * | BX40: * | CA40: A | CB40: I | CC40: F | CD40: * | CE40: * | CG40: A | CH40: I | CI40: T | CJ40: * | CK40: T | CM40: A | CN40: I | CO40: * | CP40: * | CQ40: *
AP41: B | AQ41: * | AR41: T | AS41: * | AV41: B | AW41: * | AX41: * | AY41: * | BB41: B | BC41: * | BD41: * | BE41: * | BI41: B | BJ41: * | BK41: T | BL41: * | BO41: B | BP41: * | BQ41: * | BR41: * | BU41: B | BV41: * | BW41: * | BX41: * | CB41: B | CC41: * | CD41: T | CE41: * | CH41: B | CI41: * | CJ41: * | CK41: * | CN41: B | CO41: * | CP41: * | CQ41: *
AP42: E | AQ42: * | AR42: * | AS42: * | AV42: E | AW42: * | AX42: * | AY42: * | BB42: E | BC42: * | BD42: * | BE42: * | BI42: E | BJ42: * | BK42: * | BL42: * | BO42: E | BP42: T | BQ42: * | BR42: * | BU42: E | BV42: * | BW42: * | BX42: * | CB42: E | CC42: * | CD42: * | CE42: * | CH42: E | CI42: T | CJ42: * | CK42: * | CN42: E | CO42: * | CP42: * | CQ42: *
B44: No | E44: B | K44: B | Q44: B | T44: Do the interiors of A and B overlap? | U44: Yes | X44: B | AD44: B | AJ44: B | AM44: Does the interior of A include the exterior of B? | AN44: Yes | AQ44: B | AW44: B | BC44: B | BF44: Does the interior of B include the exterior of A? | BG44: No | BJ44: B | BP44: B | BV44: B | BY44: A Contains B
E45: I | F45: B | G45: E | K45: I | L45: B | M45: E | Q45: I | R45: B | S45: E | X45: I | Y45: B | Z45: E | AD45: I | AE45: B | AF45: E | AJ45: I | AK45: B | AL45: E | AQ45: I | AR45: B | AS45: E | AW45: I | AX45: B | AY45: E | BC45: I | BD45: B | BE45: E | BJ45: I | BK45: B | BL45: E | BP45: I | BQ45: B | BR45: E | BV45: I | BW45: B | BX45: E
C46: A | D46: I | E46: * | F46: * | G46: * | I46: A | J46: I | K46: * | L46: * | M46: * | O46: A | P46: I | Q46: * | R46: * | S46: * | V46: A | W46: I | X46: T | Y46: * | Z46: * | AB46: A | AC46: I | AD46: * | AE46: * | AF46: * | AH46: A | AI46: I | AJ46: * | AK46: * | AL46: * | AO46: A | AP46: I | AQ46: T | AR46: * | AS46: T | AU46: A | AV46: I | AW46: * | AX46: * | AY46: * | BA46: A | BB46: I | BC46: * | BD46: * | BE46: * | BH46: A | BI46: I | BJ46: T | BK46: * | BL46: T | BN46: A | BO46: I | BP46: * | BQ46: * | BR46: * | BT46: A | BU46: I | BV46: * | BW46: * | BX46: *
D47: B | E47: * | F47: F | G47: * | J47: B | K47: * | L47: * | M47: * | P47: B | Q47: * | R47: * | S47: * | W47: B | X47: * | Y47: F | Z47: * | AC47: B | AD47: * | AE47: * | AF47: * | AI47: B | AJ47: * | AK47: * | AL47: * | AP47: B | AQ47: * | AR47: F | AS47: * | AV47: B | AW47: * | AX47: * | AY47: * | BB47: B | BC47: * | BD47: * | BE47: * | BI47: B | BJ47: * | BK47: F | BL47: * | BO47: B | BP47: * | BQ47: * | BR47: * | BU47: B | BV47: * | BW47: * | BX47: *
D48: E | E48: * | F48: * | G48: * | J48: E | K48: * | L48: * | M48: * | P48: E | Q48: * | R48: * | S48: * | W48: E | X48: * | Y48: * | Z48: * | AC48: E | AD48: * | AE48: * | AF48: * | AI48: E | AJ48: * | AK48: * | AL48: * | AP48: E | AQ48: * | AR48: * | AS48: * | AV48: E | AW48: * | AX48: * | AY48: * | BB48: E | BC48: * | BD48: * | BE48: * | BI48: E | BJ48: F | BK48: * | BL48: * | BO48: E | BP48: * | BQ48: * | BR48: * | BU48: E | BV48: * | BW48: * | BX48: *
...

Sheet DE-9IM Matrixes
V1: Region Test | AF1: Exterior Test | AP1: Hull Test | BB1: Region Test | BC1: Exterior Test | BD1: Hull Test
A2: ='Descision Matrix'!BY2 -> A Overlaps B | D2: B | E2: 0 | F2: 0 | G2: ='Descision Matrix'!BM2 -> 0 | J2: B | K2: 0 | L2: 0 | M2: ='Descision Matrix'!BS2 -> 0 | P2: B | Q2: 0 | R2: 0 | T2: =A2 -> A Overlaps B | V2: =D4 -> T | W2: =E4 -> * | X2: =F4 -> T | Y2: =D5 -> * | Z2: =E5 -> * | AA2: =F5 -> * | AB2: =D6 -> T | AC2: =E6 -> * | AD2: =F6 -> * | AF2: =J4 -> * | AG2: =K4 -> * | AH2: =L4 -> * | AI2: =J5 -> * | AJ2: =K5 -> * | AK2: =L5 -> * | AL2: =J6 -> * | AM2: =K6 -> * | AN2: =L6 -> * | AP2: =P4 -> * | AQ2: =Q4 -> * | AR2: =R4 -> * | AS2: =P5 -> * | AT2: =Q5 -> * | AU2: =R5 -> * | AV2: =P6 -> * | AW2: =Q6 -> * | AX2: =R6 -> * | BA2: =T2 -> A Overlaps B | BB2: =CONCATENATE(V2,W2,X2,Y2,Z2,AA2,AB2,AC2,AD2) -> T*T***T** | BC2: =CONCATENATE(AF2,AG2,AH2,AI2,AJ2,AK2,AL2,AM2,AN2) -> ********* | BD2: =CONCATENATE(AP2,AQ2,AR2,AS2,AT2,AU2,AV2,AW2,AX2) -> *********
A3: ='Descision Matrix'!BY3 -> 0 | D3: I | E3: B | F3: E | G3: ='Descision Matrix'!BM3 -> 0 | J3: I | K3: B | L3: E | M3: ='Descision Matrix'!BS3 -> 0 | P3: I | Q3: B | R3: E
A4: ='Descision Matrix'!BY4 -> 0 | B4: A | C4: I | D4: ='Descision Matrix'!BJ4 -> T | E4: ='Descision Matrix'!BK4 -> * | F4: ='Descision Matrix'!BL4 -> T | G4: ='Descision Matrix'!BM4 -> 0 | H4: A | I4: I | J4: ='Descision Matrix'!BP4 -> * | K4: ='Descision Matrix'!BQ4 -> * | L4: ='Descision Matrix'!BR4 -> * | M4: ='Descision Matrix'!BS4 -> 0 | N4: A | O4: I | P4: ='Descision Matrix'!BV4 -> * | Q4: ='Descision Matrix'!BW4 -> * | R4: ='Descision Matrix'!BX4 -> *
A5: ='Descision Matrix'!BY5 -> 0 | B5: 0 | C5: B | D5: ='Descision Matrix'!BJ5 -> * | E5: ='Descision Matrix'!BK5 -> * | F5: ='Descision Matrix'!BL5 -> * | G5: ='Descision Matrix'!BM5 -> 0 | H5: 0 | I5: B | J5: ='Descision Matrix'!BP5 -> * | K5: ='Descision Matrix'!BQ5 -> * | L5: ='Descision Matrix'!BR5 -> * | M5: ='Descision Matrix'!BS5 -> 0 | N5: 0 | O5: B | P5: ='Descision Matrix'!BV5 -> * | Q5: ='Descision Matrix'!BW5 -> * | R5: ='Descision Matrix'!BX5 -> *
A6: ='Descision Matrix'!BY6 -> 0 | B6: 0 | C6: E | D6: ='Descision Matrix'!BJ6 -> T | E6: ='Descision Matrix'!BK6 -> * | F6: ='Descision Matrix'!BL6 -> * | G6: ='Descision Matrix'!BM6 -> 0 | H6: 0 | I6: E | J6: ='Descision Matrix'!BP6 -> * | K6: ='Descision Matrix'!BQ6 -> * | L6: ='Descision Matrix'!BR6 -> * | M6: ='Descision Matrix'!BS6 -> 0 | N6: 0 | O6: E | P6: ='Descision Matrix'!BV6 -> * | Q6: ='Descision Matrix'!BW6 -> * | R6: ='Descision Matrix'!BX6 -> *
A7: ='Descision Matrix'!BY8 -> A is Partitioned by B | D7: B | E7: 0 | F7: 0 | G7: ='Descision Matrix'!BM7 -> 0 | J7: B | K7: 0 | L7: 0 | M7: ='Descision Matrix'!BS7 -> 0 | P7: B | Q7: 0 | R7: 0 | T7: =A7 -> A is Partitioned by B | V7: =D9 -> T | W7: =E9 -> * | X7: =F9 -> T | Y7: =D10 -> * | Z7: =E10 -> T | AA7: =F10 -> * | AB7: =D11 -> F | AC7: =E11 -> * | AD7: =F11 -> * | AF7: =J9 -> * | AG7: =K9 -> * | AH7: =L9 -> * | AI7: =J10 -> * | AJ7: =K10 -> * | AK7: =L10 -> * | AL7: =J11 -> * | AM7: =K11 -> * | AN7: =L11 -> * | AP7: =P9 -> * | AQ7: =Q9 -> * | AR7: =R9 -> * | AS7: =P10 -> * | AT7: =Q10 -> * | AU7: =R10 -> * | AV7: =P11 -> * | AW7: =Q11 -> * | AX7: =R11 -> * | BA7: =T7 -> A is Partitioned by B | BB7: =CONCATENATE(V7,W7,X7,Y7,Z7,AA7,AB7,AC7,AD7) -> T*T*T*F** | BC7: =CONCATENATE(AF7,AG7,AH7,AI7,AJ7,AK7,AL7,AM7,AN7) -> ********* | BD7: =CONCATENATE(AP7,AQ7,AR7,AS7,AT7,AU7,AV7,AW7,AX7) -> *********
A8: ='Descision Matrix'!BY9 -> 0 | D8: I | E8: B | F8: E | G8: ='Descision Matrix'!BM8 -> 0 | J8: I | K8: B | L8: E | M8: ='Descision Matrix'!BS8 -> 0 | P8: I | Q8: B | R8: E
A9: ='Descision Matrix'!BY10 -> 0 | B9: A | C9: I | D9: ='Descision Matrix'!BJ10 -> T | E9: ='Descision Matrix'!BK10 -> * | F9: ='Descision Matrix'!BL10 -> T | G9: ='Descision Matrix'!BM10 -> 0 | H9: A | I9: I | J9: ='Descision Matrix'!BP10 -> * | K9: ='Descision Matrix'!BQ10 -> * | L9: ='Descision Matrix'!BR10 -> * | M9: ='Descision Matrix'!BS10 -> 0 | N9: A | O9: I | P9: ='Descision Matrix'!BV10 -> * | Q9: ='Descision Matrix'!BW10 -> * | R9: ='Descision Matrix'!BX10 -> *
A10: ='Descision Matrix'!BY11 -> 0 | B10: 0 | C10: B | D10: ='Descision Matrix'!BJ11 -> * | E10: ='Descision Matrix'!BK11 -> T | F10: ='Descision Matrix'!BL11 -> * | G10: ='Descision Matrix'!BM11 -> 0 | H10: 0 | I10: B | J10: ='Descision Matrix'!BP11 -> * | K10: ='Descision Matrix'!BQ11 -> * | L10: ='Descision Matrix'!BR11 -> * | M10: ='Descision Matrix'!BS11 -> 0 | N10: 0 | O10: B | P10: ='Descision Matrix'!BV11 -> * | Q10: ='Descision Matrix'!BW11 -> * | R10: ='Descision Matrix'!BX11 -> *
A11: ='Descision Matrix'!BY12 -> 0 | B11: 0 | C11: E | D11: ='Descision Matrix'!BJ12 -> F | E11: ='Descision Matrix'!BK12 -> * | F11: ='Descision Matrix'!BL12 -> * | G11: ='Descision Matrix'!BM12 -> 0 | H11: 0 | I11: E | J11: ='Descision Matrix'!BP12 -> * | K11: ='Descision Matrix'!BQ12 -> * | L11: ='Descision Matrix'!BR12 -> * | M11: ='Descision Matrix'!BS12 -> 0 | N11: 0 | O11: E | P11: ='Descision Matrix'!BV12 -> * | Q11: ='Descision Matrix'!BW12 -> * | R11: ='Descision Matrix'!BX12 -> *
A12: ='Descision Matrix'!BY14 -> A Partitions B | D12: B | E12: 0 | F12: 0 | G12: ='Descision Matrix'!BM13 -> 0 | J12: B | K12: 0 | L12: 0 | M12: ='Descision Matrix'!BS13 -> 0 | P12: B | Q12: 0 | R12: 0 | T12: =A12 -> A Partitions B | V12: =D14 -> T | W12: =E14 -> * | X12: =F14 -> F | Y12: =D15 -> * | Z12: =E15 -> T | AA12: =F15 -> * | AB12: =D16 -> T | AC12: =E16 -> * | AD12: =F16 -> * | AF12: =J14 -> * | AG12: =K14 -> * | AH12: =L14 -> * | AI12: =J15 -> * | AJ12: =K15 -> * | AK12: =L15 -> * | AL12: =J16 -> * | AM12: =K16 -> * | AN12: =L16 -> * | AP12: =P14 -> * | AQ12: =Q14 -> * | AR12: =R14 -> * | AS12: =P15 -> * | AT12: =Q15 -> * | AU12: =R15 -> * | AV12: =P16 -> * | AW12: =Q16 -> * | AX12: =R16 -> * | BA12: =T12 -> A Partitions B | BB12: =CONCATENATE(V12,W12,X12,Y12,Z12,AA12,AB12,AC12,AD12) -> T*F*T*T** | BC12: =CONCATENATE(AF12,AG12,AH12,AI12,AJ12,AK12,AL12,AM12,AN12) -> ********* | BD12: =CONCATENATE(AP12,AQ12,AR12,AS12,AT12,AU12,AV12,AW12,AX12) -> *********
A13: ='Descision Matrix'!BY15 -> 0 | D13: I | E13: B | F13: E | G13: ='Descision Matrix'!BM14 -> 0 | J13: I | K13: B | L13: E | M13: ='Descision Matrix'!BS14 -> 0 | P13: I | Q13: B | R13: E
A14: ='Descision Matrix'!BY16 -> 0 | B14: A | C14: I | D14: ='Descision Matrix'!BJ16 -> T | E14: ='Descision Matrix'!BK16 -> * | F14: ='Descision Matrix'!BL16 -> F | G14: ='Descision Matrix'!BM16 -> 0 | H14: A | I14: I | J14: ='Descision Matrix'!BP16 -> * | K14: ='Descision Matrix'!BQ16 -> * | L14: ='Descision Matrix'!BR16 -> * | M14: ='Descision Matrix'!BS16 -> 0 | N14: A | O14: I | P14: ='Descision Matrix'!BV16 -> * | Q14: ='Descision Matrix'!BW16 -> * | R14: ='Descision Matrix'!BX16 -> *
A15: ='Descision Matrix'!BY17 -> 0 | B15: 0 | C15: B | D15: ='Descision Matrix'!BJ17 -> * | E15: ='Descision Matrix'!BK17 -> T | F15: ='Descision Matrix'!BL17 -> * | G15: ='Descision Matrix'!BM17 -> 0 | H15: 0 | I15: B | J15: ='Descision Matrix'!BP17 -> * | K15: ='Descision Matrix'!BQ17 -> * | L15: ='Descision Matrix'!BR17 -> * | M15: ='Descision Matrix'!BS17 -> 0 | N15: 0 | O15: B | P15: ='Descision Matrix'!BV17 -> * | Q15: ='Descision Matrix'!BW17 -> * | R15: ='Descision Matrix'!BX17 -> *
A16: ='Descision Matrix'!BY18 -> 0 | B16: 0 | C16: E | D16: ='Descision Matrix'!BJ18 -> T | E16: ='Descision Matrix'!BK18 -> * | F16: ='Descision Matrix'!BL18 -> * | G16: ='Descision Matrix'!BM18 -> 0 | H16: 0 | I16: E | J16: ='Descision Matrix'!BP18 -> * | K16: ='Descision Matrix'!BQ18 -> * | L16: ='Descision Matrix'!BR18 -> * | M16: ='Descision Matrix'!BS18 -> 0 | N16: 0 | O16: E | P16: ='Descision Matrix'!BV18 -> * | Q16: ='Descision Matrix'!BW18 -> * | R16: ='Descision Matrix'!BX18 -> *
A17: ='Descision Matrix'!BY20 -> A Equals B | D17: B | E17: 0 | F17: 0 | G17: ='Descision Matrix'!BM19 -> 0 | J17: B | K17: 0 | L17: 0 | M17: ='Descision Matrix'!BS19 -> 0 | P17: B | Q17: 0 | R17: 0 | T17: =A17 -> A Equals B | V17: =D19 -> T | W17: =E19 -> * | X17: =F19 -> F | Y17: =D20 -> * | Z17: =E20 -> T | AA17: =F20 -> * | AB17: =D21 -> F | AC17: =E21 -> * | AD17: =F21 -> * | AF17: =J19 -> * | AG17: =K19 -> * | AH17: =L19 -> * | AI17: =J20 -> * | AJ17: =K20 -> * | AK17: =L20 -> * | AL17: =J21 -> * | AM17: =K21 -> * | AN17: =L21 -> * | AP17: =P19 -> * | AQ17: =Q19 -> * | AR17: =R19 -> * | AS17: =P20 -> * | AT17: =Q20 -> * | AU17: =R20 -> * | AV17: =P21 -> * | AW17: =Q21 -> * | AX17: =R21 -> * | BA17: =T17 -> A Equals B | BB17: =CONCATENATE(V17,W17,X17,Y17,Z17,AA17,AB17,AC17,AD17) -> T*F*T*F** | BC17: =CONCATENATE(AF17,AG17,AH17,AI17,AJ17,AK17,AL17,AM17,AN17) -> ********* | BD17: =CONCATENATE(AP17,AQ17,AR17,AS17,AT17,AU17,AV17,AW17,AX17) -> *********
A18: ='Descision Matrix'!BY21 -> 0 | D18: I | E18: B | F18: E | G18: ='Descision Matrix'!BM20 -> 0 | J18: I | K18: B | L18: E | M18: ='Descision Matrix'!BS20 -> 0 | P18: I | Q18: B | R18: E
A19: ='Descision Matrix'!BY22 -> 0 | B19: A | C19: I | D19: ='Descision Matrix'!BJ22 -> T | E19: ='Descision Matrix'!BK22 -> * | F19: ='Descision Matrix'!BL22 -> F | G19: ='Descision Matrix'!BM22 -> 0 | H19: A | I19: I | J19: ='Descision Matrix'!BP22 -> * | K19: ='Descision Matrix'!BQ22 -> * | L19: ='Descision Matrix'!BR22 -> * | M19: ='Descision Matrix'!BS22 -> 0 | N19: A | O19: I | P19: ='Descision Matrix'!BV22 -> * | Q19: ='Descision Matrix'!BW22 -> * | R19: ='Descision Matrix'!BX22 -> *
A20: ='Descision Matrix'!BY23 -> 0 | B20: 0 | C20: B | D20: ='Descision Matrix'!BJ23 -> * | E20: ='Descision Matrix'!BK23 -> T | F20: ='Descision Matrix'!BL23 -> * | G20: ='Descision Matrix'!BM23 -> 0 | H20: 0 | I20: B | J20: ='Descision Matrix'!BP23 -> * | K20: ='Descision Matrix'!BQ23 -> * | L20: ='Descision Matrix'!BR23 -> * | M20: ='Descision Matrix'!BS23 -> 0 | N20: 0 | O20: B | P20: ='Descision Matrix'!BV23 -> * | Q20: ='Descision Matrix'!BW23 -> * | R20: ='Descision Matrix'!BX23 -> *
A21: ='Descision Matrix'!BY24 -> 0 | B21: 0 | C21: E | D21: ='Descision Matrix'!BJ24 -> F | E21: ='Descision Matrix'!BK24 -> * | F21: ='Descision Matrix'!BL24 -> * | G21: ='Descision Matrix'!BM24 -> 0 | H21: 0 | I21: E | J21: ='Descision Matrix'!BP24 -> * | K21: ='Descision Matrix'!BQ24 -> * | L21: ='Descision Matrix'!BR24 -> * | M21: ='Descision Matrix'!BS24 -> 0 | N21: 0 | O21: E | P21: ='Descision Matrix'!BV24 -> * | Q21: ='Descision Matrix'!BW24 -> * | R21: ='Descision Matrix'!BX24 -> *
A22: ='Descision Matrix'!DK26 -> A Confines B | D22: B | E22: 0 | F22: 0 | G22: ='Descision Matrix'!BM25 -> 0 | J22: B | K22: 0 | L22: 0 | M22: ='Descision Matrix'!BS25 -> 0 | P22: B | Q22: 0 | R22: 0 | T22: =A22 -> A Confines B | V22: =D24 -> F | W22: =E24 -> * | X22: =F24 -> * | Y22: =D25 -> * | Z22: =E25 -> T | AA22: =F25 -> * | AB22: =D26 -> * | AC22: =E26 -> * | AD22: =F26 -> * | AF22: =J24 -> T | AG22: =K24 -> * | AH22: =L24 -> T | AI22: =J25 -> * | AJ22: =K25 -> * | AK22: =L25 -> * | AL22: =J26 -> F | AM22: =K26 -> * | AN22: =L26 -> * | AP22: =P24 -> * | AQ22: =Q24 -> * | AR22: =R24 -> * | AS22: =P25 -> * | AT22: =Q25 -> * | AU22: =R25 -> * | AV22: =P26 -> * | AW22: =Q26 -> * | AX22: =R26 -> * | BA22: =T22 -> A Confines B | BB22: =CONCATENATE(V22,W22,X22,Y22,Z22,AA22,AB22,AC22,AD22) -> F***T**** | BC22: =CONCATENATE(AF22,AG22,AH22,AI22,AJ22,AK22,AL22,AM22,AN22) -> T*T***F** | BD22: =CONCATENATE(AP22,AQ22,AR22,AS22,AT22,AU22,AV22,AW22,AX22) -> *********
A23: ='Descision Matrix'!DK27 -> 0 | D23: I | E23: B | F23: E | G23: ='Descision Matrix'!BM26 -> 0 | J23: I | K23: B | L23: E | M23: ='Descision Matrix'!BS26 -> 0 | P23: I | Q23: B | R23: E
A24: ='Descision Matrix'!DK28 -> 0 | B24: A | C24: I | D24: ='Descision Matrix'!CC28 -> F | E24: ='Descision Matrix'!CD28 -> * | F24: ='Descision Matrix'!CE28 -> * | G24: ='Descision Matrix'!CF28 -> 0 | H24: A | I24: I | J24: ='Descision Matrix'!CI28 -> T | K24: ='Descision Matrix'!CJ28 -> * | L24: ='Descision Matrix'!CK28 -> T | M24: ='Descision Matrix'!CL28 -> 0 | N24: A | O24: I | P24: ='Descision Matrix'!CO28 -> * | Q24: ='Descision Matrix'!CP28 -> * | R24: ='Descision Matrix'!CQ28 -> *
A25: ='Descision Matrix'!DK29 -> 0 | B25: 0 | C25: B | D25: ='Descision Matrix'!CC29 -> * | E25: ='Descision Matrix'!CD29 -> T | F25: ='Descision Matrix'!CE29 -> * | G25: ='Descision Matrix'!CF29 -> 0 | H25: 0 | I25: B | J25: ='Descision Matrix'!CI29 -> * | K25: ='Descision Matrix'!CJ29 -> * | L25: ='Descision Matrix'!CK29 -> * | M25: ='Descision Matrix'!CL29 -> 0 | N25: 0 | O25: B | P25: ='Descision Matrix'!CO29 -> * | Q25: ='Descision Matrix'!CP29 -> * | R25: ='Descision Matrix'!CQ29 -> *
A26: ='Descision Matrix'!DK30 -> 0 | B26: 0 | C26: E | D26: ='Descision Matrix'!CC30 -> * | E26: ='Descision Matrix'!CD30 -> * | F26: ='Descision Matrix'!CE30 -> * | G26: ='Descision Matrix'!CF30 -> 0 | H26: 0 | I26: E | J26: ='Descision Matrix'!CI30 -> F | K26: ='Descision Matrix'!CJ30 -> * | L26: ='Descision Matrix'!CK30 -> * | M26: ='Descision Matrix'!CL30 -> 0 | N26: 0 | O26: E | P26: ='Descision Matrix'!CO30 -> * | Q26: ='Descision Matrix'!CP30 -> * | R26: ='Descision Matrix'!CQ30 -> *
A27: ='Descision Matrix'!DK32 -> A is Confined by B | D27: B | E27: 0 | F27: 0 | G27: ='Descision Matrix'!BM31 -> 0 | J27: B | K27: 0 | L27: 0 | M27: ='Descision Matrix'!BS31 -> 0 | P27: B | Q27: 0 | R27: 0 | T27: =A27 -> A is Confined by B | V27: =D29 -> F | W27: =E29 -> * | X27: =F29 -> * | Y27: =D30 -> * | Z27: =E30 -> T | AA27: =F30 -> * | AB27: =D31 -> * | AC27: =E31 -> * | AD27: =F31 -> * | AF27: =J29 -> T | AG27: =K29 -> * | AH27: =L29 -> F | AI27: =J30 -> * | AJ27: =K30 -> * | AK27: =L30 -> * | AL27: =J31 -> T | AM27: =K31 -> * | AN27: =L31 -> * | AP27: =P29 -> * | AQ27: =Q29 -> * | AR27: =R29 -> * | AS27: =P30 -> * | AT27: =Q30 -> * | AU27: =R30 -> * | AV27: =P31 -> * | AW27: =Q31 -> * | AX27: =R31 -> * | BA27: =T27 -> A is Confined by B | BB27: =CONCATENATE(V27,W27,X27,Y27,Z27,AA27,AB27,AC27,AD27) -> F***T**** | BC27: =CONCATENATE(AF27,AG27,AH27,AI27,AJ27,AK27,AL27,AM27,AN27) -> T*F***T** | BD27: =CONCATENATE(AP27,AQ27,AR27,AS27,AT27,AU27,AV27,AW27,AX27) -> *********
A28: ='Descision Matrix'!DK33 -> 0 | D28: I | E28: B | F28: E | G28: ='Descision Matrix'!BM32 -> 0 | J28: I | K28: B | L28: E | M28: ='Descision Matrix'!BS32 -> 0 | P28: I | Q28: B | R28: E
A29: ='Descision Matrix'!DK34 -> 0 | B29: A | C29: I | D29: ='Descision Matrix'!CC34 -> F | E29: ='Descision Matrix'!CD34 -> * | F29: ='Descision Matrix'!CE34 -> * | G29: ='Descision Matrix'!CF34 -> 0 | H29: A | I29: I | J29: ='Descision Matrix'!CI34 -> T | K29: ='Descision Matrix'!CJ34 -> * | L29: ='Descision Matrix'!CK34 -> F | M29: ='Descision Matrix'!CL34 -> 0 | N29: A | O29: I | P29: ='Descision Matrix'!CO34 -> * | Q29: ='Descision Matrix'!CP34 -> * | R29: ='Descision Matrix'!CQ34 -> *
A30: ='Descision Matrix'!DK35 -> 0 | B30: 0 | C30: B | D30: ='Descision Matrix'!CC35 -> * | E30: ='Descision Matrix'!CD35 -> T | F30: ='Descision Matrix'!CE35 -> * | G30: ='Descision Matrix'!CF35 -> 0 | H30: 0 | I30: B | J30: ='Descision Matrix'!CI35 -> * | K30: ='Descision Matrix'!CJ35 -> * | L30: ='Descision Matrix'!CK35 -> * | M30: ='Descision Matrix'!CL35 -> 0 | N30: 0 | O30: B | P30: ='Descision Matrix'!CO35 -> * | Q30: ='Descision Matrix'!CP35 -> * | R30: ='Descision Matrix'!CQ35 -> *
A31: ='Descision Matrix'!DK36 -> 0 | B31: 0 | C31: E | D31: ='Descision Matrix'!CC36 -> * | E31: ='Descision Matrix'!CD36 -> * | F31: ='Descision Matrix'!CE36 -> * | G31: ='Descision Matrix'!CF36 -> 0 | H31: 0 | I31: E | J31: ='Descision Matrix'!CI36 -> T | K31: ='Descision Matrix'!CJ36 -> * | L31: ='Descision Matrix'!CK36 -> * | M31: ='Descision Matrix'!CL36 -> 0 | N31: 0 | O31: E | P31: ='Descision Matrix'!CO36 -> * | Q31: ='Descision Matrix'!CP36 -> * | R31: ='Descision Matrix'!CQ36 -> *
A32: ='Descision Matrix'!BY38 -> A Borders B | D32: B | E32: 0 | F32: 0 | G32: ='Descision Matrix'!BM37 -> 0 | J32: B | K32: 0 | L32: 0 | M32: ='Descision Matrix'!BS37 -> 0 | P32: B | Q32: 0 | R32: 0 | T32: =A32 -> A Borders B | V32: =D34 -> F | W32: =E34 -> * | X32: =F34 -> * | Y32: =D35 -> * | Z32: =E35 -> T | AA32: =F35 -> * | AB32: =D36 -> * | AC32: =E36 -> * | AD32: =F36 -> * | AF32: =J34 -> F | AG32: =K34 -> * | AH32: =L34 -> T | AI32: =J35 -> * | AJ32: =K35 -> * | AK32: =L35 -> * | AL32: =J36 -> T | AM32: =K36 -> * | AN32: =L36 -> * | AP32: =P34 -> * | AQ32: =Q34 -> * | AR32: =R34 -> * | AS32: =P35 -> * | AT32: =Q35 -> * | AU32: =R35 -> * | AV32: =P36 -> * | AW32: =Q36 -> * | AX32: =R36 -> * | BA32: =T32 -> A Borders B | BB32: =CONCATENATE(V32,W32,X32,Y32,Z32,AA32,AB32,AC32,AD32) -> F***T**** | BC32: =CONCATENATE(AF32,AG32,AH32,AI32,AJ32,AK32,AL32,AM32,AN32) -> F*T***T** | BD32: =CONCATENATE(AP32,AQ32,AR32,AS32,AT32,AU32,AV32,AW32,AX32) -> *********
A33: ='Descision Matrix'!BY39 -> 0 | D33: I | E33: B | F33: E | G33: ='Descision Matrix'!BM38 -> 0 | J33: I | K33: B | L33: E | M33: ='Descision Matrix'!BS38 -> 0 | P33: I | Q33: B | R33: E
A34: ='Descision Matrix'!BY40 -> 0 | B34: A | C34: I | D34: ='Descision Matrix'!BJ40 -> F | E34: ='Descision Matrix'!BK40 -> * | F34: ='Descision Matrix'!BL40 -> * | G34: ='Descision Matrix'!BM40 -> 0 | H34: A | I34: I | J34: ='Descision Matrix'!BP40 -> F | K34: ='Descision Matrix'!BQ40 -> * | L34: ='Descision Matrix'!BR40 -> T | M34: ='Descision Matrix'!BS40 -> 0 | N34: A | O34: I | P34: ='Descision Matrix'!BV40 -> * | Q34: ='Descision Matrix'!BW40 -> * | R34: ='Descision Matrix'!BX40 -> *
A35: ='Descision Matrix'!BY41 -> 0 | B35: 0 | C35: B | D35: ='Descision Matrix'!BJ41 -> * | E35: ='Descision Matrix'!BK41 -> T | F35: ='Descision Matrix'!BL41 -> * | G35: ='Descision Matrix'!BM41 -> 0 | H35: 0 | I35: B | J35: ='Descision Matrix'!BP41 -> * | K35: ='Descision Matrix'!BQ41 -> * | L35: ='Descision Matrix'!BR41 -> * | M35: ='Descision Matrix'!BS41 -> 0 | N35: 0 | O35: B | P35: ='Descision Matrix'!BV41 -> * | Q35: ='Descision Matrix'!BW41 -> * | R35: ='Descision Matrix'!BX41 -> *
A36: ='Descision Matrix'!BY42 -> 0 | B36: 0 | C36: E | D36: ='Descision Matrix'!BJ42 -> * | E36: ='Descision Matrix'!BK42 -> * | F36: ='Descision Matrix'!BL42 -> * | G36: ='Descision Matrix'!BM42 -> 0 | H36: 0 | I36: E | J36: ='Descision Matrix'!BP42 -> T | K36: ='Descision Matrix'!BQ42 -> * | L36: ='Descision Matrix'!BR42 -> * | M36: ='Descision Matrix'!BS42 -> 0 | N36: 0 | O36: E | P36: ='Descision Matrix'!BV42 -> * | Q36: ='Descision Matrix'!BW42 -> * | R36: ='Descision Matrix'!BX42 -> *
A37: ='Descision Matrix'!BY44 -> A Contains B | D37: B | E37: 0 | F37: 0 | G37: ='Descision Matrix'!BM43 -> 0 | J37: B | K37: 0 | L37: 0 | M37: ='Descision Matrix'!BS43 -> 0 | P37: B | Q37: 0 | R37: 0 | T37: =A37 -> A Contains B | V37: =D39 -> T | W37: =E39 -> * | X37: =F39 -> T | Y37: =D40 -> * | Z37: =E40 -> F | AA37: =F40 -> * | AB37: =D41 -> F | AC37: =E41 -> * | AD37: =F41 -> * | AF37: =J39 -> * | AG37: =K39 -> * | AH37: =L39 -> * | AI37: =J40 -> * | AJ37: =K40 -> * | AK37: =L40 -> * | AL37: =J41 -> * | AM37: =K41 -> * | AN37: =L41 -> * | AP37: =P39 -> * | AQ37: =Q39 -> * | AR37: =R39 -> * | AS37: =P40 -> * | AT37: =Q40 -> * | AU37: =R40 -> * | AV37: =P41 -> * | AW37: =Q41 -> * | AX37: =R41 -> * | BA37: =T37 -> A Contains B | BB37: =CONCATENATE(V37,W37,X37,Y37,Z37,AA37,AB37,AC37,AD37) -> T*T*F*F** | BC37: =CONCATENATE(AF37,AG37,AH37,AI37,AJ37,AK37,AL37,AM37,AN37) -> ********* | BD37: =CONCATENATE(AP37,AQ37,AR37,AS37,AT37,AU37,AV37,AW37,AX37) -> *********
A38: ='Descision Matrix'!BY45 -> 0 | D38: I | E38: B | F38: E | G38: ='Descision Matrix'!BM44 -> 0 | J38: I | K38: B | L38: E | M38: ='Descision Matrix'!BS44 -> 0 | P38: I | Q38: B | R38: E
A39: ='Descision Matrix'!BY46 -> 0 | B39: A | C39: I | D39: ='Descision Matrix'!BJ46 -> T | E39: ='Descision Matrix'!BK46 -> * | F39: ='Descision Matrix'!BL46 -> T | G39: ='Descision Matrix'!BM46 -> 0 | H39: A | I39: I | J39: ='Descision Matrix'!BP46 -> * | K39: ='Descision Matrix'!BQ46 -> * | L39: ='Descision Matrix'!BR46 -> * | M39: ='Descision Matrix'!BS46 -> 0 | N39: A | O39: I | P39: ='Descision Matrix'!BV46 -> * | Q39: ='Descision Matrix'!BW46 -> * | R39: ='Descision Matrix'!BX46 -> *
A40: ='Descision Matrix'!BY47 -> 0 | B40: 0 | C40: B | D40: ='Descision Matrix'!BJ47 -> * | E40: ='Descision Matrix'!BK47 -> F | F40: ='Descision Matrix'!BL47 -> * | G40: ='Descision Matrix'!BM47 -> 0 | H40: 0 | I40: B | J40: ='Descision Matrix'!BP47 -> * | K40: ='Descision Matrix'!BQ47 -> * | L40: ='Descision Matrix'!BR47 -> * | M40: ='Descision Matrix'!BS47 -> 0 | N40: 0 | O40: B | P40: ='Descision Matrix'!BV47 -> * | Q40: ='Descision Matrix'!BW47 -> * | R40: ='Descision Matrix'!BX47 -> *
...

Sheet Inverted Relations
A1: Standard Matricies | T1: Complementary Matricies
B2: Region | H2: External | N2: Hull | U2: Region | AA2: External | AG2: Hull | AO2: Region Test | AY2: Exterior Test | BI2: Hull Test
A3: ='DE-9IM Matrixes'!A2 -> A Overlaps B | D3: B | J3: B | P3: B | T3: =SUBSTITUTE(SUBSTITUTE(SUBSTITUTE(SUBSTITUTE(A3,"A","x"),"B","A"),"x","B"),"Ao","Bo") -> B Overlaps A | W3: B | AC3: B | AI3: B | AM3: =A3 -> A Overlaps B | AO3: =D5 -> T | AP3: =E5 -> * | AQ3: =F5 -> T | AR3: =D6 -> * | AS3: =E6 -> * | AT3: =F6 -> * | AU3: =D7 -> T | AV3: =E7 -> * | AW3: =F7 -> * | AY3: =J5 -> * | AZ3: =K5 -> * | BA3: =L5 -> * | BB3: =J6 -> * | BC3: =K6 -> * | BD3: =L6 -> * | BE3: =J7 -> * | BF3: =K7 -> * | BG3: =L7 -> * | BI3: =P5 -> * | BJ3: =Q5 -> * | BK3: =R5 -> * | BL3: =P6 -> * | BM3: =Q6 -> * | BN3: =R6 -> * | BO3: =P7 -> * | BP3: =Q7 -> * | BQ3: =R7 -> *
D4: I | E4: B | F4: E | J4: I | K4: B | L4: E | P4: I | Q4: B | R4: E | W4: I | X4: B | Y4: E | AC4: I | AD4: B | AE4: E | AI4: I | AJ4: B | AK4: E | AM4: expected | AO4: =AO3 -> T | AP4: =IF(ISERROR(SEARCH("Not",$AM6)),AP3,AR3) -> * | AQ4: =IF(ISERROR(SEARCH("Not",$AM6)),AQ3,AU3) -> T | AR4: =IF(ISERROR(SEARCH("Not",$AM6)),AR3,AP3) -> * | AS4: =AS3 -> * | AT4: =IF(ISERROR(SEARCH("Not",$AM6)),AT3,AV3) -> * | AU4: =IF(ISERROR(SEARCH("Not",$AM6)),AU3,AQ3) -> T | AV4: =IF(ISERROR(SEARCH("Not",$AM6)),AV3,AT3) -> * | AW4: =AW3 -> * | AY4: =AY3 -> * | AZ4: =IF(ISERROR(SEARCH("Not",$AM6)),AZ3,BB3) -> * | BA4: =IF(ISERROR(SEARCH("Not",$AM6)),BA3,BE3) -> * | BB4: =IF(ISERROR(SEARCH("Not",$AM6)),BB3,AZ3) -> * | BC4: =BC3 -> * | BD4: =IF(ISERROR(SEARCH("Not",$AM6)),BD3,BF3) -> * | BE4: =IF(ISERROR(SEARCH("Not",$AM6)),BE3,BA3) -> * | BF4: =IF(ISERROR(SEARCH("Not",$AM6)),BF3,BD3) -> * | BG4: =BG3 -> * | BI4: =BI3 -> * | BJ4: =IF(ISERROR(SEARCH("Not",$AM6)),BJ3,BL3) -> * | BK4: =IF(ISERROR(SEARCH("Not",$AM6)),BK3,BO3) -> * | BL4: =IF(ISERROR(SEARCH("Not",$AM6)),BL3,BJ3) -> * | BM4: =BM3 -> * | BN4: =IF(ISERROR(SEARCH("Not",$AM6)),BN3,BP3) -> * | BO4: =IF(ISERROR(SEARCH("Not",$AM6)),BO3,BK3) -> * | BP4: =IF(ISERROR(SEARCH("Not",$AM6)),BP3,BN3) -> * | BQ4: =BQ3 -> *
B5: A | C5: I | D5: ='DE-9IM Matrixes'!D4 -> T | E5: ='DE-9IM Matrixes'!E4 -> * | F5: ='DE-9IM Matrixes'!F4 -> T | H5: A | I5: I | J5: ='DE-9IM Matrixes'!J4 -> * | K5: ='DE-9IM Matrixes'!K4 -> * | L5: ='DE-9IM Matrixes'!L4 -> * | N5: A | O5: I | P5: ='DE-9IM Matrixes'!P4 -> * | Q5: ='DE-9IM Matrixes'!Q4 -> * | R5: ='DE-9IM Matrixes'!R4 -> * | U5: A | V5: I | W5: =D5 -> T | X5: =D6 -> * | Y5: =D7 -> T | AA5: A | AB5: I | AC5: =J5 -> * | AD5: =J6 -> * | AE5: =J7 -> * | AG5: A | AH5: I | AI5: =P5 -> * | AJ5: =P6 -> * | AK5: =P7 -> * | AM5: =T3 -> B Overlaps A | AO5: =W5 -> T | AP5: =X5 -> * | AQ5: =Y5 -> T | AR5: =W6 -> * | AS5: =X6 -> * | AT5: =Y6 -> * | AU5: =W7 -> T | AV5: =X7 -> * | AW5: =Y7 -> * | AY5: =AC5 -> * | AZ5: =AD5 -> * | BA5: =AE5 -> * | BB5: =AC6 -> * | BC5: =AD6 -> * | BD5: =AE6 -> * | BE5: =AC7 -> * | BF5: =AD7 -> * | BG5: =AE7 -> * | BI5: =AI5 -> * | BJ5: =AJ5 -> * | BK5: =AK5 -> * | BL5: =AI6 -> * | BM5: =AJ6 -> * | BN5: =AK6 -> * | BO5: =AI7 -> * | BP5: =AJ7 -> * | BQ5: =AK7 -> *
C6: B | D6: ='DE-9IM Matrixes'!D5 -> * | E6: ='DE-9IM Matrixes'!E5 -> * | F6: ='DE-9IM Matrixes'!F5 -> * | I6: B | J6: ='DE-9IM Matrixes'!J5 -> * | K6: ='DE-9IM Matrixes'!K5 -> * | L6: ='DE-9IM Matrixes'!L5 -> * | O6: B | P6: ='DE-9IM Matrixes'!P5 -> * | Q6: ='DE-9IM Matrixes'!Q5 -> * | R6: ='DE-9IM Matrixes'!R5 -> * | V6: B | W6: =E5 -> * | X6: =E6 -> * | Y6: =E7 -> * | AB6: B | AC6: =K5 -> * | AD6: =K6 -> * | AE6: =K7 -> * | AH6: B | AI6: =Q5 -> * | AJ6: =Q6 -> * | AK6: =Q7 -> * | AM6: Symmetric | AO6: =IF(AO4=AO5,"","X") | AP6: =IF(AP4=AP5,"","X") | AQ6: =IF(AQ4=AQ5,"","X") | AR6: =IF(AR4=AR5,"","X") | AS6: =IF(AS4=AS5,"","X") | AT6: =IF(AT4=AT5,"","X") | AU6: =IF(AU4=AU5,"","X") | AV6: =IF(AV4=AV5,"","X") | ... BR6: =IF(BR4=BR5,"","X")
C7: E | D7: ='DE-9IM Matrixes'!D6 -> T | E7: ='DE-9IM Matrixes'!E6 -> * | F7: ='DE-9IM Matrixes'!F6 -> * | I7: E | J7: ='DE-9IM Matrixes'!J6 -> * | K7: ='DE-9IM Matrixes'!K6 -> * | L7: ='DE-9IM Matrixes'!L6 -> * | O7: E | P7: ='DE-9IM Matrixes'!P6 -> * | Q7: ='DE-9IM Matrixes'!Q6 -> * | R7: ='DE-9IM Matrixes'!R6 -> * | V7: E | W7: =F5 -> T | X7: =F6 -> * | Y7: =F7 -> * | AB7: E | AC7: =L5 -> * | AD7: =L6 -> * | AE7: =L7 -> * | AH7: E | AI7: =R5 -> * | AJ7: =R6 -> * | AK7: =R7 -> *
A8: ='DE-9IM Matrixes'!A7 -> A is Partitioned by B | D8: B | J8: B | P8: B | T8: =SUBSTITUTE(SUBSTITUTE(SUBSTITUTE(SUBSTITUTE(A8,"A","x"),"B","A"),"x","B"),"Ao","Bo") -> B is Partitioned by A | W8: B | AC8: B | AI8: B | AM8: =A8 -> A is Partitioned by B | AO8: =D10 -> T | AP8: =E10 -> * | AQ8: =F10 -> T | AR8: =D11 -> * | AS8: =E11 -> T | AT8: =F11 -> * | AU8: =D12 -> F | AV8: =E12 -> * | AW8: =F12 -> * | AY8: =J10 -> * | AZ8: =K10 -> * | BA8: =L10 -> * | BB8: =J11 -> * | BC8: =K11 -> * | BD8: =L11 -> * | BE8: =J12 -> * | BF8: =K12 -> * | BG8: =L12 -> * | BI8: =P10 -> * | BJ8: =Q10 -> * | BK8: =R10 -> * | BL8: =P11 -> * | BM8: =Q11 -> * | BN8: =R11 -> * | BO8: =P12 -> * | BP8: =Q12 -> * | BQ8: =R12 -> *
D9: I | E9: B | F9: E | J9: I | K9: B | L9: E | P9: I | Q9: B | R9: E | W9: I | X9: B | Y9: E | AC9: I | AD9: B | AE9: E | AI9: I | AJ9: B | AK9: E | AM9: expected | AO9: =AO8 -> T | AP9: =IF(ISERROR(SEARCH("Not",$AM11)),AP8,AR8) -> * | AQ9: =IF(ISERROR(SEARCH("Not",$AM11)),AQ8,AU8) -> F | AR9: =IF(ISERROR(SEARCH("Not",$AM11)),AR8,AP8) -> * | AS9: =AS8 -> T | AT9: =IF(ISERROR(SEARCH("Not",$AM11)),AT8,AV8) -> * | AU9: =IF(ISERROR(SEARCH("Not",$AM11)),AU8,AQ8) -> T | AV9: =IF(ISERROR(SEARCH("Not",$AM11)),AV8,AT8) -> * | AW9: =AW8 -> * | AY9: =AY8 -> * | AZ9: =IF(ISERROR(SEARCH("Not",$AM11)),AZ8,BB8) -> * | BA9: =IF(ISERROR(SEARCH("Not",$AM11)),BA8,BE8) -> * | BB9: =IF(ISERROR(SEARCH("Not",$AM11)),BB8,AZ8) -> * | BC9: =BC8 -> * | BD9: =IF(ISERROR(SEARCH("Not",$AM11)),BD8,BF8) -> * | BE9: =IF(ISERROR(SEARCH("Not",$AM11)),BE8,BA8) -> * | BF9: =IF(ISERROR(SEARCH("Not",$AM11)),BF8,BD8) -> * | BG9: =BG8 -> * | BI9: =BI8 -> * | BJ9: =IF(ISERROR(SEARCH("Not",$AM11)),BJ8,BL8) -> * | BK9: =IF(ISERROR(SEARCH("Not",$AM11)),BK8,BO8) -> * | BL9: =IF(ISERROR(SEARCH("Not",$AM11)),BL8,BJ8) -> * | BM9: =BM8 -> * | BN9: =IF(ISERROR(SEARCH("Not",$AM11)),BN8,BP8) -> * | BO9: =IF(ISERROR(SEARCH("Not",$AM11)),BO8,BK8) -> * | BP9: =IF(ISERROR(SEARCH("Not",$AM11)),BP8,BN8) -> * | BQ9: =BQ8 -> *
B10: A | C10: I | D10: ='DE-9IM Matrixes'!D9 -> T | E10: ='DE-9IM Matrixes'!E9 -> * | F10: ='DE-9IM Matrixes'!F9 -> T | H10: A | I10: I | J10: ='DE-9IM Matrixes'!J9 -> * | K10: ='DE-9IM Matrixes'!K9 -> * | L10: ='DE-9IM Matrixes'!L9 -> * | N10: A | O10: I | P10: ='DE-9IM Matrixes'!P9 -> * | Q10: ='DE-9IM Matrixes'!Q9 -> * | R10: ='DE-9IM Matrixes'!R9 -> * | U10: A | V10: I | W10: =D10 -> T | X10: =D11 -> * | Y10: =D12 -> F | AA10: A | AB10: I | AC10: =J10 -> * | AD10: =J11 -> * | AE10: =J12 -> * | AG10: A | AH10: I | AI10: =P10 -> * | AJ10: =P11 -> * | AK10: =P12 -> * | AM10: =T8 -> B is Partitioned by A | AO10: =W10 -> T | AP10: =X10 -> * | AQ10: =Y10 -> F | AR10: =W11 -> * | AS10: =X11 -> T | AT10: =Y11 -> * | AU10: =W12 -> T | AV10: =X12 -> * | AW10: =Y12 -> * | AY10: =AC10 -> * | AZ10: =AD10 -> * | BA10: =AE10 -> * | BB10: =AC11 -> * | BC10: =AD11 -> * | BD10: =AE11 -> * | BE10: =AC12 -> * | BF10: =AD12 -> * | BG10: =AE12 -> * | BI10: =AI10 -> * | BJ10: =AJ10 -> * | BK10: =AK10 -> * | BL10: =AI11 -> * | BM10: =AJ11 -> * | BN10: =AK11 -> * | BO10: =AI12 -> * | BP10: =AJ12 -> * | BQ10: =AK12 -> *
C11: B | D11: ='DE-9IM Matrixes'!D10 -> * | E11: ='DE-9IM Matrixes'!E10 -> T | F11: ='DE-9IM Matrixes'!F10 -> * | I11: B | J11: ='DE-9IM Matrixes'!J10 -> * | K11: ='DE-9IM Matrixes'!K10 -> * | L11: ='DE-9IM Matrixes'!L10 -> * | O11: B | P11: ='DE-9IM Matrixes'!P10 -> * | Q11: ='DE-9IM Matrixes'!Q10 -> * | R11: ='DE-9IM Matrixes'!R10 -> * | V11: B | W11: =E10 -> * | X11: =E11 -> T | Y11: =E12 -> * | AB11: B | AC11: =K10 -> * | AD11: =K11 -> * | AE11: =K12 -> * | AH11: B | AI11: =Q10 -> * | AJ11: =Q11 -> * | AK11: =Q12 -> * | AM11: Not Symmetric | AO11: =IF(AO9=AO10,"","X") | AP11: =IF(AP9=AP10,"","X") | AQ11: =IF(AQ9=AQ10,"","X") | AR11: =IF(AR9=AR10,"","X") | AS11: =IF(AS9=AS10,"","X") | AT11: =IF(AT9=AT10,"","X") | AU11: =IF(AU9=AU10,"","X") | AV11: =IF(AV9=AV10,"","X") | ... BR11: =IF(BR9=BR10,"","X")
C12: E | D12: ='DE-9IM Matrixes'!D11 -> F | E12: ='DE-9IM Matrixes'!E11 -> * | F12: ='DE-9IM Matrixes'!F11 -> * | I12: E | J12: ='DE-9IM Matrixes'!J11 -> * | K12: ='DE-9IM Matrixes'!K11 -> * | L12: ='DE-9IM Matrixes'!L11 -> * | O12: E | P12: ='DE-9IM Matrixes'!P11 -> * | Q12: ='DE-9IM Matrixes'!Q11 -> * | R12: ='DE-9IM Matrixes'!R11 -> * | V12: E | W12: =F10 -> T | X12: =F11 -> * | Y12: =F12 -> * | AB12: E | AC12: =L10 -> * | AD12: =L11 -> * | AE12: =L12 -> * | AH12: E | AI12: =R10 -> * | AJ12: =R11 -> * | AK12: =R12 -> *
A13: ='DE-9IM Matrixes'!A12 -> A Partitions B | D13: B | J13: B | P13: B | T13: =SUBSTITUTE(SUBSTITUTE(SUBSTITUTE(SUBSTITUTE(A13,"A","x"),"B","A"),"x","B"),"Ao","Bo") -> B Partitions A | W13: B | AC13: B | AI13: B | AM13: =A13 -> A Partitions B | AO13: =D15 -> T | AP13: =E15 -> * | AQ13: =F15 -> F | AR13: =D16 -> * | AS13: =E16 -> T | AT13: =F16 -> * | AU13: =D17 -> T | AV13: =E17 -> * | AW13: =F17 -> * | AY13: =J15 -> * | AZ13: =K15 -> * | BA13: =L15 -> * | BB13: =J16 -> * | BC13: =K16 -> * | BD13: =L16 -> * | BE13: =J17 -> * | BF13: =K17 -> * | BG13: =L17 -> * | BI13: =P15 -> * | BJ13: =Q15 -> * | BK13: =R15 -> * | BL13: =P16 -> * | BM13: =Q16 -> * | BN13: =R16 -> * | BO13: =P17 -> * | BP13: =Q17 -> * | BQ13: =R17 -> *
D14: I | E14: B | F14: E | J14: I | K14: B | L14: E | P14: I | Q14: B | R14: E | W14: I | X14: B | Y14: E | AC14: I | AD14: B | AE14: E | AI14: I | AJ14: B | AK14: E | AM14: expected | AO14: =AO13 -> T | AP14: =IF(ISERROR(SEARCH("Not",$AM16)),AP13,AR13) -> * | AQ14: =IF(ISERROR(SEARCH("Not",$AM16)),AQ13,AU13) -> T | AR14: =IF(ISERROR(SEARCH("Not",$AM16)),AR13,AP13) -> * | AS14: =AS13 -> T | AT14: =IF(ISERROR(SEARCH("Not",$AM16)),AT13,AV13) -> * | AU14: =IF(ISERROR(SEARCH("Not",$AM16)),AU13,AQ13) -> F | AV14: =IF(ISERROR(SEARCH("Not",$AM16)),AV13,AT13) -> * | AW14: =AW13 -> * | AY14: =AY13 -> * | AZ14: =IF(ISERROR(SEARCH("Not",$AM16)),AZ13,BB13) -> * | BA14: =IF(ISERROR(SEARCH("Not",$AM16)),BA13,BE13) -> * | BB14: =IF(ISERROR(SEARCH("Not",$AM16)),BB13,AZ13) -> * | BC14: =BC13 -> * | BD14: =IF(ISERROR(SEARCH("Not",$AM16)),BD13,BF13) -> * | BE14: =IF(ISERROR(SEARCH("Not",$AM16)),BE13,BA13) -> * | BF14: =IF(ISERROR(SEARCH("Not",$AM16)),BF13,BD13) -> * | BG14: =BG13 -> * | BI14: =BI13 -> * | BJ14: =IF(ISERROR(SEARCH("Not",$AM16)),BJ13,BL13) -> * | BK14: =IF(ISERROR(SEARCH("Not",$AM16)),BK13,BO13) -> * | BL14: =IF(ISERROR(SEARCH("Not",$AM16)),BL13,BJ13) -> * | BM14: =BM13 -> * | BN14: =IF(ISERROR(SEARCH("Not",$AM16)),BN13,BP13) -> * | BO14: =IF(ISERROR(SEARCH("Not",$AM16)),BO13,BK13) -> * | BP14: =IF(ISERROR(SEARCH("Not",$AM16)),BP13,BN13) -> * | BQ14: =BQ13 -> *
B15: A | C15: I | D15: ='DE-9IM Matrixes'!D14 -> T | E15: ='DE-9IM Matrixes'!E14 -> * | F15: ='DE-9IM Matrixes'!F14 -> F | H15: A | I15: I | J15: ='DE-9IM Matrixes'!J14 -> * | K15: ='DE-9IM Matrixes'!K14 -> * | L15: ='DE-9IM Matrixes'!L14 -> * | N15: A | O15: I | P15: ='DE-9IM Matrixes'!P14 -> * | Q15: ='DE-9IM Matrixes'!Q14 -> * | R15: ='DE-9IM Matrixes'!R14 -> * | U15: A | V15: I | W15: =D15 -> T | X15: =D16 -> * | Y15: =D17 -> T | AA15: A | AB15: I | AC15: =J15 -> * | AD15: =J16 -> * | AE15: =J17 -> * | AG15: A | AH15: I | AI15: =P15 -> * | AJ15: =P16 -> * | AK15: =P17 -> * | AM15: =T13 -> B Partitions A | AO15: =W15 -> T | AP15: =X15 -> * | AQ15: =Y15 -> T | AR15: =W16 -> * | AS15: =X16 -> T | AT15: =Y16 -> * | AU15: =W17 -> F | AV15: =X17 -> * | AW15: =Y17 -> * | AY15: =AC15 -> * | AZ15: =AD15 -> * | BA15: =AE15 -> * | BB15: =AC16 -> * | BC15: =AD16 -> * | BD15: =AE16 -> * | BE15: =AC17 -> * | BF15: =AD17 -> * | BG15: =AE17 -> * | BI15: =AI15 -> * | BJ15: =AJ15 -> * | BK15: =AK15 -> * | BL15: =AI16 -> * | BM15: =AJ16 -> * | BN15: =AK16 -> * | BO15: =AI17 -> * | BP15: =AJ17 -> * | BQ15: =AK17 -> *
C16: B | D16: ='DE-9IM Matrixes'!D15 -> * | E16: ='DE-9IM Matrixes'!E15 -> T | F16: ='DE-9IM Matrixes'!F15 -> * | I16: B | J16: ='DE-9IM Matrixes'!J15 -> * | K16: ='DE-9IM Matrixes'!K15 -> * | L16: ='DE-9IM Matrixes'!L15 -> * | O16: B | P16: ='DE-9IM Matrixes'!P15 -> * | Q16: ='DE-9IM Matrixes'!Q15 -> * | R16: ='DE-9IM Matrixes'!R15 -> * | V16: B | W16: =E15 -> * | X16: =E16 -> T | Y16: =E17 -> * | AB16: B | AC16: =K15 -> * | AD16: =K16 -> * | AE16: =K17 -> * | AH16: B | AI16: =Q15 -> * | AJ16: =Q16 -> * | AK16: =Q17 -> * | AM16: Not Symmetric | AO16: =IF(AO14=AO15,"","X") | AP16: =IF(AP14=AP15,"","X") | AQ16: =IF(AQ14=AQ15,"","X") | AR16: =IF(AR14=AR15,"","X") | AS16: =IF(AS14=AS15,"","X") | AT16: =IF(AT14=AT15,"","X") | AU16: =IF(AU14=AU15,"","X") | AV16: =IF(AV14=AV15,"","X") | ... BR16: =IF(BR14=BR15,"","X")
C17: E | D17: ='DE-9IM Matrixes'!D16 -> T | E17: ='DE-9IM Matrixes'!E16 -> * | F17: ='DE-9IM Matrixes'!F16 -> * | I17: E | J17: ='DE-9IM Matrixes'!J16 -> * | K17: ='DE-9IM Matrixes'!K16 -> * | L17: ='DE-9IM Matrixes'!L16 -> * | O17: E | P17: ='DE-9IM Matrixes'!P16 -> * | Q17: ='DE-9IM Matrixes'!Q16 -> * | R17: ='DE-9IM Matrixes'!R16 -> * | V17: E | W17: =F15 -> F | X17: =F16 -> * | Y17: =F17 -> * | AB17: E | AC17: =L15 -> * | AD17: =L16 -> * | AE17: =L17 -> * | AH17: E | AI17: =R15 -> * | AJ17: =R16 -> * | AK17: =R17 -> *
A18: ='DE-9IM Matrixes'!A17 -> A Equals B | D18: B | J18: B | P18: B | T18: =SUBSTITUTE(SUBSTITUTE(SUBSTITUTE(SUBSTITUTE(A18,"A","x"),"B","A"),"x","B"),"Ao","Bo") -> B Equals A | W18: B | AC18: B | AI18: B | AM18: =A18 -> A Equals B | AO18: =D20 -> T | AP18: =E20 -> * | AQ18: =F20 -> F | AR18: =D21 -> * | AS18: =E21 -> T | AT18: =F21 -> * | AU18: =D22 -> F | AV18: =E22 -> * | AW18: =F22 -> * | AY18: =J20 -> * | AZ18: =K20 -> * | BA18: =L20 -> * | BB18: =J21 -> * | BC18: =K21 -> * | BD18: =L21 -> * | BE18: =J22 -> * | BF18: =K22 -> * | BG18: =L22 -> * | BI18: =P20 -> * | BJ18: =Q20 -> * | BK18: =R20 -> * | BL18: =P21 -> * | BM18: =Q21 -> * | BN18: =R21 -> * | BO18: =P22 -> * | BP18: =Q22 -> * | BQ18: =R22 -> *
D19: I | E19: B | F19: E | J19: I | K19: B | L19: E | P19: I | Q19: B | R19: E | W19: I | X19: B | Y19: E | AC19: I | AD19: B | AE19: E | AI19: I | AJ19: B | AK19: E | AM19: expected | AO19: =AO18 -> T | AP19: =IF(ISERROR(SEARCH("Not",$AM21)),AP18,AR18) -> * | AQ19: =IF(ISERROR(SEARCH("Not",$AM21)),AQ18,AU18) -> F | AR19: =IF(ISERROR(SEARCH("Not",$AM21)),AR18,AP18) -> * | AS19: =AS18 -> T | AT19: =IF(ISERROR(SEARCH("Not",$AM21)),AT18,AV18) -> * | AU19: =IF(ISERROR(SEARCH("Not",$AM21)),AU18,AQ18) -> F | AV19: =IF(ISERROR(SEARCH("Not",$AM21)),AV18,AT18) -> * | AW19: =AW18 -> * | AY19: =AY18 -> * | AZ19: =IF(ISERROR(SEARCH("Not",$AM21)),AZ18,BB18) -> * | BA19: =IF(ISERROR(SEARCH("Not",$AM21)),BA18,BE18) -> * | BB19: =IF(ISERROR(SEARCH("Not",$AM21)),BB18,AZ18) -> * | BC19: =BC18 -> * | BD19: =IF(ISERROR(SEARCH("Not",$AM21)),BD18,BF18) -> * | BE19: =IF(ISERROR(SEARCH("Not",$AM21)),BE18,BA18) -> * | BF19: =IF(ISERROR(SEARCH("Not",$AM21)),BF18,BD18) -> * | BG19: =BG18 -> * | BI19: =BI18 -> * | BJ19: =IF(ISERROR(SEARCH("Not",$AM21)),BJ18,BL18) -> * | BK19: =IF(ISERROR(SEARCH("Not",$AM21)),BK18,BO18) -> * | BL19: =IF(ISERROR(SEARCH("Not",$AM21)),BL18,BJ18) -> * | BM19: =BM18 -> * | BN19: =IF(ISERROR(SEARCH("Not",$AM21)),BN18,BP18) -> * | BO19: =IF(ISERROR(SEARCH("Not",$AM21)),BO18,BK18) -> * | BP19: =IF(ISERROR(SEARCH("Not",$AM21)),BP18,BN18) -> * | BQ19: =BQ18 -> *
B20: A | C20: I | D20: ='DE-9IM Matrixes'!D19 -> T | E20: ='DE-9IM Matrixes'!E19 -> * | F20: ='DE-9IM Matrixes'!F19 -> F | H20: A | I20: I | J20: ='DE-9IM Matrixes'!J19 -> * | K20: ='DE-9IM Matrixes'!K19 -> * | L20: ='DE-9IM Matrixes'!L19 -> * | N20: A | O20: I | P20: ='DE-9IM Matrixes'!P19 -> * | Q20: ='DE-9IM Matrixes'!Q19 -> * | R20: ='DE-9IM Matrixes'!R19 -> * | U20: A | V20: I | W20: =D20 -> T | X20: =D21 -> * | Y20: =D22 -> F | AA20: A | AB20: I | AC20: =J20 -> * | AD20: =J21 -> * | AE20: =J22 -> * | AG20: A | AH20: I | AI20: =P20 -> * | AJ20: =P21 -> * | AK20: =P22 -> * | AM20: =T18 -> B Equals A | AO20: =W20 -> T | AP20: =X20 -> * | AQ20: =Y20 -> F | AR20: =W21 -> * | AS20: =X21 -> T | AT20: =Y21 -> * | AU20: =W22 -> F | AV20: =X22 -> * | AW20: =Y22 -> * | AY20: =AC20 -> * | AZ20: =AD20 -> * | BA20: =AE20 -> * | BB20: =AC21 -> * | BC20: =AD21 -> * | BD20: =AE21 -> * | BE20: =AC22 -> * | BF20: =AD22 -> * | BG20: =AE22 -> * | BI20: =AI20 -> * | BJ20: =AJ20 -> * | BK20: =AK20 -> * | BL20: =AI21 -> * | BM20: =AJ21 -> * | BN20: =AK21 -> * | BO20: =AI22 -> * | BP20: =AJ22 -> * | BQ20: =AK22 -> *
C21: B | D21: ='DE-9IM Matrixes'!D20 -> * | E21: ='DE-9IM Matrixes'!E20 -> T | F21: ='DE-9IM Matrixes'!F20 -> * | I21: B | J21: ='DE-9IM Matrixes'!J20 -> * | K21: ='DE-9IM Matrixes'!K20 -> * | L21: ='DE-9IM Matrixes'!L20 -> * | O21: B | P21: ='DE-9IM Matrixes'!P20 -> * | Q21: ='DE-9IM Matrixes'!Q20 -> * | R21: ='DE-9IM Matrixes'!R20 -> * | V21: B | W21: =E20 -> * | X21: =E21 -> T | Y21: =E22 -> * | AB21: B | AC21: =K20 -> * | AD21: =K21 -> * | AE21: =K22 -> * | AH21: B | AI21: =Q20 -> * | AJ21: =Q21 -> * | AK21: =Q22 -> * | AM21: Symmetric | AO21: =IF(AO19=AO20,"","X") | AP21: =IF(AP19=AP20,"","X") | AQ21: =IF(AQ19=AQ20,"","X") | AR21: =IF(AR19=AR20,"","X") | AS21: =IF(AS19=AS20,"","X") | AT21: =IF(AT19=AT20,"","X") | AU21: =IF(AU19=AU20,"","X") | AV21: =IF(AV19=AV20,"","X") | ... BR21: =IF(BR19=BR20,"","X")
C22: E | D22: ='DE-9IM Matrixes'!D21 -> F | E22: ='DE-9IM Matrixes'!E21 -> * | F22: ='DE-9IM Matrixes'!F21 -> * | I22: E | J22: ='DE-9IM Matrixes'!J21 -> * | K22: ='DE-9IM Matrixes'!K21 -> * | L22: ='DE-9IM Matrixes'!L21 -> * | O22: E | P22: ='DE-9IM Matrixes'!P21 -> * | Q22: ='DE-9IM Matrixes'!Q21 -> * | R22: ='DE-9IM Matrixes'!R21 -> * | V22: E | W22: =F20 -> F | X22: =F21 -> * | Y22: =F22 -> * | AB22: E | AC22: =L20 -> * | AD22: =L21 -> * | AE22: =L22 -> * | AH22: E | AI22: =R20 -> * | AJ22: =R21 -> * | AK22: =R22 -> *
A23: ='DE-9IM Matrixes'!A22 -> A Confines B | D23: B | J23: B | P23: B | T23: =SUBSTITUTE(SUBSTITUTE(SUBSTITUTE(SUBSTITUTE(A23,"A","x"),"B","A"),"x","B"),"Ao","Bo") -> B Confines A | W23: B | AC23: B | AI23: B | AM23: =A23 -> A Confines B | AO23: =D25 -> F | AP23: =E25 -> * | AQ23: =F25 -> * | AR23: =D26 -> * | AS23: =E26 -> T | AT23: =F26 -> * | AU23: =D27 -> * | AV23: =E27 -> * | AW23: =F27 -> * | AY23: =J25 -> T | AZ23: =K25 -> * | BA23: =L25 -> T | BB23: =J26 -> * | BC23: =K26 -> * | BD23: =L26 -> * | BE23: =J27 -> F | BF23: =K27 -> * | BG23: =L27 -> * | BI23: =P25 -> * | BJ23: =Q25 -> * | BK23: =R25 -> * | BL23: =P26 -> * | BM23: =Q26 -> * | BN23: =R26 -> * | BO23: =P27 -> * | BP23: =Q27 -> * | BQ23: =R27 -> *
D24: I | E24: B | F24: E | J24: I | K24: B | L24: E | P24: I | Q24: B | R24: E | W24: I | X24: B | Y24: E | AC24: I | AD24: B | AE24: E | AI24: I | AJ24: B | AK24: E | AM24: expected | AO24: =AO23 -> F | AP24: =IF(ISERROR(SEARCH("Not",$AM26)),AP23,AR23) -> * | AQ24: =IF(ISERROR(SEARCH("Not",$AM26)),AQ23,AU23) -> * | AR24: =IF(ISERROR(SEARCH("Not",$AM26)),AR23,AP23) -> * | AS24: =AS23 -> T | AT24: =IF(ISERROR(SEARCH("Not",$AM26)),AT23,AV23) -> * | AU24: =IF(ISERROR(SEARCH("Not",$AM26)),AU23,AQ23) -> * | AV24: =IF(ISERROR(SEARCH("Not",$AM26)),AV23,AT23) -> * | AW24: =AW23 -> * | AY24: =AY23 -> T | AZ24: =IF(ISERROR(SEARCH("Not",$AM26)),AZ23,BB23) -> * | BA24: =IF(ISERROR(SEARCH("Not",$AM26)),BA23,BE23) -> F | BB24: =IF(ISERROR(SEARCH("Not",$AM26)),BB23,AZ23) -> * | BC24: =BC23 -> * | BD24: =IF(ISERROR(SEARCH("Not",$AM26)),BD23,BF23) -> * | BE24: =IF(ISERROR(SEARCH("Not",$AM26)),BE23,BA23) -> T | BF24: =IF(ISERROR(SEARCH("Not",$AM26)),BF23,BD23) -> * | BG24: =BG23 -> * | BI24: =BI23 -> * | BJ24: =IF(ISERROR(SEARCH("Not",$AM26)),BJ23,BL23) -> * | BK24: =IF(ISERROR(SEARCH("Not",$AM26)),BK23,BO23) -> * | BL24: =IF(ISERROR(SEARCH("Not",$AM26)),BL23,BJ23) -> * | BM24: =BM23 -> * | BN24: =IF(ISERROR(SEARCH("Not",$AM26)),BN23,BP23) -> * | BO24: =IF(ISERROR(SEARCH("Not",$AM26)),BO23,BK23) -> * | BP24: =IF(ISERROR(SEARCH("Not",$AM26)),BP23,BN23) -> * | BQ24: =BQ23 -> *
B25: A | C25: I | D25: ='DE-9IM Matrixes'!D24 -> F | E25: ='DE-9IM Matrixes'!E24 -> * | F25: ='DE-9IM Matrixes'!F24 -> * | H25: A | I25: I | J25: ='DE-9IM Matrixes'!J24 -> T | K25: ='DE-9IM Matrixes'!K24 -> * | L25: ='DE-9IM Matrixes'!L24 -> T | N25: A | O25: I | P25: ='DE-9IM Matrixes'!P24 -> * | Q25: ='DE-9IM Matrixes'!Q24 -> * | R25: ='DE-9IM Matrixes'!R24 -> * | U25: A | V25: I | W25: =D25 -> F | X25: =D26 -> * | Y25: =D27 -> * | AA25: A | AB25: I | AC25: =J25 -> T | AD25: =J26 -> * | AE25: =J27 -> F | AG25: A | AH25: I | AI25: =P25 -> * | AJ25: =P26 -> * | AK25: =P27 -> * | AM25: =T23 -> B Confines A | AO25: =W25 -> F | AP25: =X25 -> * | AQ25: =Y25 -> * | AR25: =W26 -> * | AS25: =X26 -> T | AT25: =Y26 -> * | AU25: =W27 -> * | AV25: =X27 -> * | AW25: =Y27 -> * | AY25: =AC25 -> T | AZ25: =AD25 -> * | BA25: =AE25 -> F | BB25: =AC26 -> * | BC25: =AD26 -> * | BD25: =AE26 -> * | BE25: =AC27 -> T | BF25: =AD27 -> * | BG25: =AE27 -> * | BI25: =AI25 -> * | BJ25: =AJ25 -> * | BK25: =AK25 -> * | BL25: =AI26 -> * | BM25: =AJ26 -> * | BN25: =AK26 -> * | BO25: =AI27 -> * | BP25: =AJ27 -> * | BQ25: =AK27 -> *
C26: B | D26: ='DE-9IM Matrixes'!D25 -> * | E26: ='DE-9IM Matrixes'!E25 -> T | F26: ='DE-9IM Matrixes'!F25 -> * | I26: B | J26: ='DE-9IM Matrixes'!J25 -> * | K26: ='DE-9IM Matrixes'!K25 -> * | L26: ='DE-9IM Matrixes'!L25 -> * | O26: B | P26: ='DE-9IM Matrixes'!P25 -> * | Q26: ='DE-9IM Matrixes'!Q25 -> * | R26: ='DE-9IM Matrixes'!R25 -> * | V26: B | W26: =E25 -> * | X26: =E26 -> T | Y26: =E27 -> * | AB26: B | AC26: =K25 -> * | AD26: =K26 -> * | AE26: =K27 -> * | AH26: B | AI26: =Q25 -> * | AJ26: =Q26 -> * | AK26: =Q27 -> * | AM26: Not Symmetric | AO26: =IF(AO24=AO25,"","X") | AP26: =IF(AP24=AP25,"","X") | AQ26: =IF(AQ24=AQ25,"","X") | AR26: =IF(AR24=AR25,"","X") | AS26: =IF(AS24=AS25,"","X") | AT26: =IF(AT24=AT25,"","X") | AU26: =IF(AU24=AU25,"","X") | AV26: =IF(AV24=AV25,"","X") | ... BR26: =IF(BR24=BR25,"","X")
C27: E | D27: ='DE-9IM Matrixes'!D26 -> * | E27: ='DE-9IM Matrixes'!E26 -> * | F27: ='DE-9IM Matrixes'!F26 -> * | I27: E | J27: ='DE-9IM Matrixes'!J26 -> F | K27: ='DE-9IM Matrixes'!K26 -> * | L27: ='DE-9IM Matrixes'!L26 -> * | O27: E | P27: ='DE-9IM Matrixes'!P26 -> * | Q27: ='DE-9IM Matrixes'!Q26 -> * | R27: ='DE-9IM Matrixes'!R26 -> * | V27: E | W27: =F25 -> * | X27: =F26 -> * | Y27: =F27 -> * | AB27: E | AC27: =L25 -> T | AD27: =L26 -> * | AE27: =L27 -> * | AH27: E | AI27: =R25 -> * | AJ27: =R26 -> * | AK27: =R27 -> *
A28: ='DE-9IM Matrixes'!A27 -> A is Confined by B | D28: B | J28: B | P28: B | T28: =SUBSTITUTE(SUBSTITUTE(SUBSTITUTE(SUBSTITUTE(A28,"A","x"),"B","A"),"x","B"),"Ao","Bo") -> B is Confined by A | W28: B | AC28: B | AI28: B | AM28: =A28 -> A is Confined by B | AO28: =D30 -> F | AP28: =E30 -> * | AQ28: =F30 -> * | AR28: =D31 -> * | AS28: =E31 -> T | AT28: =F31 -> * | AU28: =D32 -> * | AV28: =E32 -> * | AW28: =F32 -> * | AY28: =J30 -> T | AZ28: =K30 -> * | BA28: =L30 -> F | BB28: =J31 -> * | BC28: =K31 -> * | BD28: =L31 -> * | BE28: =J32 -> T | BF28: =K32 -> * | BG28: =L32 -> * | BI28: =P30 -> * | BJ28: =Q30 -> * | BK28: =R30 -> * | BL28: =P31 -> * | BM28: =Q31 -> * | BN28: =R31 -> * | BO28: =P32 -> * | BP28: =Q32 -> * | BQ28: =R32 -> *
D29: I | E29: B | F29: E | J29: I | K29: B | L29: E | P29: I | Q29: B | R29: E | W29: I | X29: B | Y29: E | AC29: I | AD29: B | AE29: E | AI29: I | AJ29: B | AK29: E | AM29: expected | AO29: =AO28 -> F | AP29: =IF(ISERROR(SEARCH("Not",$AM31)),AP28,AR28) -> * | AQ29: =IF(ISERROR(SEARCH("Not",$AM31)),AQ28,AU28) -> * | AR29: =IF(ISERROR(SEARCH("Not",$AM31)),AR28,AP28) -> * | AS29: =AS28 -> T | AT29: =IF(ISERROR(SEARCH("Not",$AM31)),AT28,AV28) -> * | AU29: =IF(ISERROR(SEARCH("Not",$AM31)),AU28,AQ28) -> * | AV29: =IF(ISERROR(SEARCH("Not",$AM31)),AV28,AT28) -> * | AW29: =AW28 -> * | AY29: =AY28 -> T | AZ29: =IF(ISERROR(SEARCH("Not",$AM31)),AZ28,BB28) -> * | BA29: =IF(ISERROR(SEARCH("Not",$AM31)),BA28,BE28) -> T | BB29: =IF(ISERROR(SEARCH("Not",$AM31)),BB28,AZ28) -> * | BC29: =BC28 -> * | BD29: =IF(ISERROR(SEARCH("Not",$AM31)),BD28,BF28) -> * | BE29: =IF(ISERROR(SEARCH("Not",$AM31)),BE28,BA28) -> F | BF29: =IF(ISERROR(SEARCH("Not",$AM31)),BF28,BD28) -> * | BG29: =BG28 -> * | BI29: =BI28 -> * | BJ29: =IF(ISERROR(SEARCH("Not",$AM31)),BJ28,BL28) -> * | BK29: =IF(ISERROR(SEARCH("Not",$AM31)),BK28,BO28) -> * | BL29: =IF(ISERROR(SEARCH("Not",$AM31)),BL28,BJ28) -> * | BM29: =BM28 -> * | BN29: =IF(ISERROR(SEARCH("Not",$AM31)),BN28,BP28) -> * | BO29: =IF(ISERROR(SEARCH("Not",$AM31)),BO28,BK28) -> * | BP29: =IF(ISERROR(SEARCH("Not",$AM31)),BP28,BN28) -> * | BQ29: =BQ28 -> *
